Workbook

Sheet Réponses au formulaire 1
A1: Horodateur | B1: Adresse e-mail | C1: Quel est votre statut ? (Etudiants/Enseignant/ Autre) | D1: Quel type de connexion internet utilisez-vous le plus ? | E1: Quel appareil utilisez-vous le plus pour communiquer sur internet ? | F1: Combien d'heures par jour passez-vous sur internet(heures) | G1: A quel point la qualité de votre connexion internet est-elle satisfaisante ? | H1: Utilisez-vous internet pour les études ou le travail ? | I1: Pour quelles activités utilisez-vous le plus internet ? | J1: Selon vous, comment les réseaux de communication ont-ils changé la façon dont les gens communiquent ?
A2: 46096.852 | B2: 25169@supnum.mr | C2: Étudiant | D2: Wi-Fi | E2: Ordinateur Portable | F2: 5 | G2: 4 | H2: Oui | I2: Réseaux sociaux, Regarder des vidéos | J2: De façon générale
A3: 46096.853 | B3: 25044@supnum.mr | C3: Autre | D3: Cable / Fibre | E3: Ordinateur de Bureau | F3: 11 | G3: 5 | H3: Non | I3: Jeux en ligne
A4: 46096.854 | B4: 25047@supnum.mr | C4: Enseignant | D4: Données mobiles (5G / 4G) | E4: Ordinateur Portable | F4: 8 | G4: 5 | H4: Non | I4: Réseaux sociaux | J4: Fjgkh
A5: 46096.857 | B5: 25051@supnum.mr | C5: Autre | D5: Cable / Fibre | E5: Ordinateur Portable | F5: 7 | G5: 2 | H5: Non | I5: Regarder des vidéos | J5: Oii
A6: 46096.857 | B6: 25130@supnum.mr | C6: Autre | D6: Wi-Fi | E6: Smartphone | F6: 5 | G6: 3 | H6: Oui | I6: Réseaux sociaux | J6: Kutf
A7: 46096.858 | B7: 250135@supnum.mr | C7: Étudiant | D7: Cable / Fibre | E7: Tablette | F7: 10 | G7: 4 | H7: Oui | I7: Jeux en ligne | J7: Bien
A8: 46096.858 | B8: 25120@spnum.mr | C8: Étudiant | D8: Wi-Fi | E8: Ordinateur Portable | F8: 11 | G8: 4 | H8: Non | I8: Réseaux sociaux | J8: Bien
A9: 46096.859 | B9: 25073@supnum.mr | C9: Autre | D9: Cable / Fibre | E9: Ordinateur Portable | F9: 19 | G9: 2 | H9: Non | I9: Recherche d'informations | J9: Uhgf
A10: 46096.885 | B10: 25036@supnum.mr | C10: Étudiant | D10: Wi-Fi | E10: Smartphone | F10: 20 | G10: 1 | H10: Oui | I10: Réseaux sociaux | J10: Communication à grande distanc,rapide
A11: 46096.943 | B11: 25164@supnum.mr | C11: Enseignet | D11: Données mobiles (5G / 4G) | E11: Ordinateur Portable | F11: 3 | G11: 5 | H11: Oui | I11: Réseaux sociaux | J11: Je ne sais pas
A12: 46096.958 | B12: azizeelgouth@gmail.com | C12: Étudiante | D12: Wi-Fi | E12: Smartphone | F12: 13 | G12: 1 | H12: Oui | I12: Etudes / Travail, Réseaux sociaux, Regarder des vidéos | J12: ….
A13: 46096.964 | B13: Medleminlebatt@gmail.com | C13: Etudient | D13: Wi-Fi | E13: Smartphone | F13: 2 | G13: 3 | H13: Oui | I13: Etudes / Travail | J13: Pas mal
A14: 46096.972 | B14: 25109@supnum.mr | C14: Étudiante | D14: Wi-Fi | E14: Smartphone | F14: 4 | G14: 4 | H14: Oui | I14: Etudes / Travail, Réseaux sociaux, Regarder des vidéos, Jeux en ligne, Recherche d'informations | J14: Les réseaux ont rendu la communication instantanée, mondiale et accessible à tous en temps réel.
A15: 46096.978 | B15: baymed000@gmail.com | C15: Etudiant | D15: Wi-Fi | E15: Smartphone | F15: 21 | G15: 1 | H15: Oui | I15: Etudes / Travail, Réseaux sociaux | J15: communication de groupes
... A18: 46096.999 | B18: medvallaichetou2@gmail.com | C18: Autre | D18: Données mobiles (5G / 4G) | E18: Smartphone | F18: 12 | G18: 3 | H18: Oui | I18: Etudes / Travail, Regarder des vidéos, Recherche d'informations | J18: Les réseaux de communication ont rendu la communication plus rapide et plus facile. Les gens peuvent échanger des messageset des photos .

Sheet Analyse
A1: Analyse des données – Réseaux Mondiaux
A3: 1. Analyse d'une question numérique
A4: Combien d'heures par jour passez-vous sur internet ?
A5: Indicateur | B5: Formule utilisée | C5: Résultat
A6: Nombre de réponses | B6: COUNT() | C6: =COUNT('Réponses au formulaire 1'!F2:F18) -> 17
A7: Minimum (heures) | B7: MIN() | C7: =MIN('Réponses au formulaire 1'!F2:F18) -> 2
A8: Maximum (heures) | B8: MAX() | C8: =MAX('Réponses au formulaire 1'!F2:F18) -> 21
A9: Moyenne (heures) | B9: AVERAGE() | C9: =AVERAGE('Réponses au formulaire 1'!F2:F18) -> 10.529412
A11: 2. Analyse d'une question catégorielle
A12: Question : Quel type de connexion internet utilisez-vous le plus ?
A13: Réponse | B13: Nombre | C13: Pourcentage
A14: Wi-Fi | B14: =COUNTIF('Réponses au formulaire 1'!D$2:D$18,A14) -> 9 | C14: =B14/B17 -> 0.52941176
A15: Cable / Fibre | B15: =COUNTIF('Réponses au formulaire 1'!D$2:D$18,A15) -> 4 | C15: =B15/B17 -> 0.23529412
A16: Données mobiles (5G / 4G) | B16: =COUNTIF('Réponses au formulaire 1'!D$2:D$18,A16) -> 4 | C16: =B16/B17 -> 0.23529412
A17: TOTAL | B17: =SUM(B14:B16) -> 17 | C17: =SUM(C14:C16) -> 1
A19: Question : Quel appareil utilisez-vous le plus pour communiquer sur internet ?
A20: Réponse | B20: Nombre | C20: Pourcentage
A21: Smartphone | B21: =COUNTIF('Réponses au formulaire 1'!E$2:E$18,A21) -> 8 | C21: =B21/B25 -> 0.47058824
A22: Ordinateur Portable | B22: =COUNTIF('Réponses au formulaire 1'!E$2:E$18,A22) -> 7 | C22: =B22/B25 -> 0.41176471
A23: Ordinateur de Bureau | B23: =COUNTIF('Réponses au formulaire 1'!E$2:E$18,A23) -> 1 | C23: =B23/B25 -> 0.058823529
A24: Tablette | B24: =COUNTIF('Réponses au formulaire 1'!E$2:E$18,A24) -> 1 | C24: =B24/B25 -> 0.058823529
A25: TOTAL | B25: =SUM(B21:B24) -> 17 | C25: =SUM(C21:C24) -> 1
A27: Question : Utilisez-vous internet pour les études ou le travail ?
A28: Réponse | B28: Nombre | C28: Pourcentage
A29: Oui | B29: =COUNTIF('Réponses au formulaire 1'!H$2:H$18,A29) -> 11 | C29: =B29/B31 -> 0.64705882
A30: Non | B30: =COUNTIF('Réponses au formulaire 1'!H$2:H$18,A30) -> 6 | C30: =B30/B31 -> 0.35294118
A31: TOTAL | B31: =SUM(B29:B30) -> 17 | C31: =SUM(C29:C30) -> 1
A33: 3. Interprétation des résultats
A34: 1. La majorité des répondants utilisent le Wi-Fi comme connexion principale, suivi du câble/fibre et des données mobiles.
A35: 2. Le smartphone est l'appareil dominant pour communiquer sur internet, suivi de l'ordinateur portable.
A36: 3. La durée moyenne de connexion quotidienne est élevée, reflétant une forte dépendance à internet.
A37: 4. Plus de 64 % des répondants utilisent internet pour leurs études ou leur travail, soulignant son rôle pédagogique.
A38: 5. Les réseaux sociaux et le divertissement dominent les usages, mais les activités académiques restent significatives.
E41: Heures | F41: Nombre
E42: 2 | F42: =COUNTIF('Réponses au formulaire 1'!F$2:F$18,E42) -> 1
E43: 3 | F43: =COUNTIF('Réponses au formulaire 1'!F$2:F$18,E43) -> 1
E44: 4 | F44: =COUNTIF('Réponses au formulaire 1'!F$2:F$18,E44) -> 1
E45: 5 | F45: =COUNTIF('Réponses au formulaire 1'!F$2:F$18,E45) -> 2
E46: 7 | F46: =COUNTIF('Réponses au formulaire 1'!F$2:F$18,E46) -> 1
E47: 8 | F47: =COUNTIF('Réponses au formulaire 1'!F$2:F$18,E47) -> 1
...
